Workbook
Name Slicer_Region: #N/A
Name Slicer_Segment: #N/A
Name Slicer_Year: #N/A

Sheet Detail1
A1: Details for Sum of Profit - Category: Technology
A3: Row ID | B3: Order ID | C3: Year | D3: Order Date | E3: Ship Date | F3: Ship Mode | G3: Customer ID | H3: Customer Name | I3: Segment | J3: Country | K3: City | L3: State | M3: Postal Code | N3: Region | O3: Product ID | P3: Category | Q3: Sub-Category | R3: Product Name | S3: Sales | T3: Quantity | U3: Discount | V3: Profit
A4: 9992 | B4: CA-2014-121258 | C4: 2014 | D4: 41697 | E4: 41702 | F4: Standard Class | G4: DB-13060 | H4: Dave Brooks | I4: Consumer | J4: United States | K4: Costa Mesa | L4: California | M4: 92627 | N4: West | O4: TEC-PH-10003645 | P4: Technology | Q4: Phones | R4: Aastra 57i VoIP phone | S4: 258.576 | T4: 2 | U4: 0.2 | V4: 19.3932
A5: 9989 | B5: CA-2014-163629 | C5: 2014 | D5: 41961 | E5: 41965 | F5: Standard Class | G5: RA-19885 | H5: Ruben Ausman | I5: Corporate | J5: United States | K5: Athens | L5: Georgia | M5: 30605 | N5: South | O5: TEC-PH-10004006 | P5: Technology | Q5: Phones | R5: Panasonic KX - TS880B Telephone | S5: 206.1 | T5: 5 | U5: 0 | V5: 55.647
A6: 9988 | B6: CA-2014-163629 | C6: 2014 | D6: 41961 | E6: 41965 | F6: Standard Class | G6: RA-19885 | H6: Ruben Ausman | I6: Corporate | J6: United States | K6: Athens | L6: Georgia | M6: 30605 | N6: South | O6: TEC-AC-10001539 | P6: Technology | Q6: Accessories | R6: Logitech G430 Surround Sound Gaming Headset with Dolby 7.1 Technology | S6: 79.99 | T6: 1 | U6: 0 | V6: 28.7964
A7: 9987 | B7: CA-2013-125794 | C7: 2013 | D7: 41547 | E7: 41551 | F7: Standard Class | G7: ML-17410 | H7: Maris LaWare | I7: Consumer | J7: United States | K7: Los Angeles | L7: California | M7: 90008 | N7: West | O7: TEC-AC-10003399 | P7: Technology | Q7: Accessories | R7: Memorex Mini Travel Drive 64 GB USB 2.0 Flash Drive | S7: 36.24 | T7: 1 | U7: 0 | V7: 15.2208
A8: 9984 | B8: US-2013-157728 | C8: 2013 | D8: 41540 | E8: 41546 | F8: Standard Class | G8: RC-19960 | H8: Ryan Crowe | I8: Consumer | J8: United States | K8: Grand Rapids | L8: Michigan | M8: 49505 | N8: Central | O8: TEC-PH-10001305 | P8: Technology | Q8: Phones | R8: Panasonic KX TS208W Corded phone | S8: 97.98 | T8: 2 | U8: 0 | V8: 27.4344
A9: 9977 | B9: US-2013-103674 | C9: 2013 | D9: 41615 | E9: 41619 | F9: Standard Class | G9: AP-10720 | H9: Anne Pryor | I9: Home Office | J9: United States | K9: Los Angeles | L9: California | M9: 90032 | N9: West | O9: TEC-PH-10002496 | P9: Technology | Q9: Phones | R9: Cisco SPA301 | S9: 249.584 | T9: 2 | U9: 0.2 | V9: 31.198
A10: 9974 | B10: US-2013-103674 | C10: 2013 | D10: 41615 | E10: 41619 | F10: Standard Class | G10: AP-10720 | H10: Anne Pryor | I10: Home Office | J10: United States | K10: Los Angeles | L10: California | M10: 90032 | N10: West | O10: TEC-PH-10004080 | P10: Technology | Q10: Phones | R10: Avaya 5410 Digital phone | S10: 271.96 | T10: 5 | U10: 0.2 | V10: 27.196
A11: 8 | B11: CA-2011-115812 | C11: 2011 | D11: 40703 | E11: 40708 | F11: Standard Class | G11: BH-11710 | H11: Brosina Hoffman | I11: Consumer | J11: United States | K11: Los Angeles | L11: California | M11: 90032 | N11: West | O11: TEC-PH-10002275 | P11: Technology | Q11: Phones | R11: Mitel 5320 IP Phone VoIP phone | S11: 907.152 | T11: 6 | U11: 0.2 | V11: 90.7152
A12: 9961 | B12: CA-2014-141446 | C12: 2014 | D12: 41899 | E12: 41901 | F12: Second Class | G12: CL-12700 | H12: Craig Leslie | I12: Home Office | J12: United States | K12: Florence | L12: Kentucky | M12: 41042 | N12: South | O12: TEC-AC-10002305 | P12: Technology | Q12: Accessories | R12: KeyTronic E03601U1 - Keyboard - Beige | S12: 18 | T12: 1 | U12: 0 | V12: 3.24
A13: 9951 | B13: CA-2014-121559 | C13: 2014 | D13: 41792 | E13: 41794 | F13: Second Class | G13: HW-14935 | H13: Helen Wasserman | I13: Corporate | J13: United States | K13: Indianapolis | L13: Indiana | M13: 46203 | N13: Central | O13: TEC-AC-10001714 | P13: Technology | Q13: Accessories | R13: Logitech MX Performance Wireless Mouse | S13: 39.89 | T13: 1 | U13: 0 | V13: 14.7593
A14: 9950 | B14: CA-2014-121559 | C14: 2014 | D14: 41792 | E14: 41794 | F14: Second Class | G14: HW-14935 | H14: Helen Wasserman | I14: Corporate | J14: United States | K14: Indianapolis | L14: Indiana | M14: 46203 | N14: Central | O14: TEC-AC-10004568 | P14: Technology | Q14: Accessories | R14: Maxell LTO Ultrium - 800 GB | S14: 83.97 | T14: 3 | U14: 0 | V14: 15.9543
A15: 12 | B15: CA-2011-115812 | C15: 2011 | D15: 40703 | E15: 40708 | F15: Standard Class | G15: BH-11710 | H15: Brosina Hoffman | I15: Consumer | J15: United States | K15: Los Angeles | L15: California | M15: 90032 | N15: West | O15: TEC-PH-10002033 | P15: Technology | Q15: Phones | R15: Konftel 250 Conference phone - Charcoal black | S15: 911.424 | T15: 4 | U15: 0.2 | V15: 68.3568
... A175: 9153 | B175: US-2012-106873 | C175: 2012 | D175: 41176 | E175: 41181 | F175: Second Class | G175: KM-16720 | H175: Kunst Miller | I175: Consumer | J175: United States | K175: Avondale | L175: Arizona | M175: 85323 | N175: West | O175: TEC-AC-10002345 | P175: Technology | Q175: Accessories | R175: HP Standard 104 key PS/2 Keyboard | S175: 23.2 | T175: 2 | U175: 0.2 | V175: 1.45
A176: 9147 | B176: US-2013-165505 | C176: 2013 | D176: 41297 | E176: 41301 | F176: Standard Class | G176: CB-12535 | H176: Claudia Bergmann | I176: Corporate | J176: United States | K176: Burlington | L176: Vermont | M176: 05408 | N176: East | O176: TEC-AC-10002926 | P176: Technology | Q176: Accessories | R176: Logitech Wireless Marathon Mouse M705 | S176: 99.98 | T176: 2 | U176: 0 | V176: 42.9914
A177: 9144 | B177: US-2014-166688 | C177: 2014 | D177: 41780 | E177: 41786 | F177: Standard Class | G177: RD-19480 | H177: Rick Duston | I177: Consumer | J177: United States | K177: Las Vegas | L177: Nevada | M177: 89115 | N177: West | O177: TEC-PH-10004094 | P177: Technology | Q177: Phones | R177: Motorola L703CM | S177: 1123.128 | T177: 9 | U177: 0.2 | V177: 70.1955
A178: 9142 | B178: CA-2013-139409 | C178: 2013 | D178: 41523 | E178: 41525 | F178: First Class | G178: FW-14395 | H178: Fred Wasserman | I178: Corporate | J178: United States | K178: New York City | L178: New York | M178: 10011 | N178: East | O178: TEC-PH-10003988 | P178: Technology | Q178: Phones | R178: LF Elite 3D Dazzle Designer Hard Case Cover, Lf Stylus Pen and Wiper For Apple Iphone 5c Mini Lite | S178: 43.6 | T178: 4 | U178: 0 | V178: 12.208
A179: 9141 | B179: CA-2014-123029 | C179: 2014 | D179: 41913 | E179: 41915 | F179: Second Class | G179: BT-11530 | H179: Bradley Talbott | I179: Home Office | J179: United States | K179: Los Angeles | L179: California | M179: 90049 | N179: West | O179: TEC-AC-10002402 | P179: Technology | Q179: Accessories | R179: Razer Kraken PRO Over Ear PC and Music Headset | S179: 159.98 | T179: 2 | U179: 0 | V179: 47.994
A180: 9140 | B180: CA-2011-106971 | C180: 2011 | D180: 40788 | E180: 40794 | F180: Standard Class | G180: BM-11785 | H180: Bryan Mills | I180: Consumer | J180: United States | K180: Buffalo Grove | L180: Illinois | M180: 60089 | N180: Central | O180: TEC-AC-10000844 | P180: Technology | Q180: Accessories | R180: Logitech Gaming G510s - Keyboard | S180: 475.944 | T180: 7 | U180: 0.2 | V180: 95.1888
A181: 9139 | B181: CA-2011-123400 | C181: 2011 | D181: 40577 | E181: 40584 | F181: Standard Class | G181: EB-13930 | H181: Eric Barreto | I181: Consumer | J181: United States | K181: Saint Petersburg | L181: Florida | M181: 33710 | N181: South | O181: TEC-PH-10002890 | P181: Technology | Q181: Phones | R181: AT&T 17929 Lendline Telephone | S181: 180.96 | T181: 5 | U181: 0.2 | V181: 13.572
A182: 9134 | B182: CA-2012-157805 | C182: 2012 | D182: 41152 | E182: 41156 | F182: Standard Class | G182: RH-19510 | H182: Rick Huthwaite | I182: Home Office | J182: United States | K182: San Diego | L182: California | M182: 92037 | N182: West | O182: TEC-PH-10004447 | P182: Technology | Q182: Phones | R182: Toshiba IPT2010-SD IP Telephone | S182: 555.96 | T182: 5 | U182: 0.2 | V182: 41.697
A183: 9116 | B183: CA-2014-153045 | C183: 2014 | D183: 41659 | E183: 41664 | F183: Second Class | G183: NS-18505 | H183: Neola Schneider | I183: Consumer | J183: United States | K183: Philadelphia | L183: Pennsylvania | M183: 19140 | N183: East | O183: TEC-PH-10001817 | P183: Technology | Q183: Phones | R183: Wilson Electronics DB Pro Signal Booster | S183: 429.6 | T183: 2 | U183: 0.4 | V183: -93.08
A184: 9115 | B184: CA-2013-135461 | C184: 2013 | D184: 41312 | E184: 41315 | F184: Second Class | G184: EB-13975 | H184: Erica Bern | I184: Corporate | J184: United States | K184: Los Angeles | L184: California | M184: 90049 | N184: West | O184: TEC-PH-10004094 | P184: Technology | Q184: Phones | R184: Motorola L703CM | S184: 623.96 | T184: 5 | U184: 0.2 | V184: 38.9975
A185: 182 | B185: CA-2011-166191 | C185: 2011 | D185: 40882 | E185: 40886 | F185: Second Class | G185: DK-13150 | H185: David Kendrick | I185: Corporate | J185: United States | K185: Decatur | L185: Illinois | M185: 62521 | N185: Central | O185: TEC-AC-10004659 | P185: Technology | Q185: Accessories | R185: Imation Secure+ Hardware Encrypted USB 2.0 Flash Drive; 16GB | S185: 408.744 | T185: 7 | U185: 0.2 | V185: 76.6395
A186: 183 | B186: CA-2011-158274 | C186: 2011 | D186: 40866 | E186: 40871 | F186: Second Class | G186: RM-19675 | H186: Robert Marley | I186: Home Office | J186: United States | K186: Monroe | L186: Louisiana | M186: 71203 | N186: South | O186: TEC-PH-10003273 | P186: Technology | Q186: Phones | R186: AT&T TR1909W | S186: 503.96 | T186: 4 | U186: 0 | V186: 131.0296
A187: 184 | B187: CA-2011-158274 | C187: 2011 | D187: 40866 | E187: 40871 | F187: Second Class | G187: RM-19675 | H187: Robert Marley | I187: Home Office | J187: United States | K187: Monroe | L187: Louisiana | M187: 71203 | N187: South | O187: TEC-PH-10004896 | P187: Technology | Q187: Phones | R187: Nokia Lumia 521 (T-Mobile) | S187: 149.95 | T187: 5 | U187: 0 | V187: 41.986
A188: 185 | B188: CA-2011-158274 | C188: 2011 | D188: 40866 | E188: 40871 | F188: Second Class | G188: RM-19675 | H188: Robert Marley | I188: Home Office | J188: United States | K188: Monroe | L188: Louisiana | M188: 71203 | N188: South | O188: TEC-AC-10002345 | P188: Technology | Q188: Accessories | R188: HP Standard 104 key PS/2 Keyboard | S188: 29 | T188: 2 | U188: 0 | V188: 7.25
... A283: 8800 | B283: CA-2011-116666 | C283: 2011 | D283: 40671 | E283: 40673 | F283: First Class | G283: KT-16480 | H283: Kean Thornton | I283: Consumer | J283: United States | K283: Philadelphia | L283: Pennsylvania | M283: 19134 | N283: East | O283: TEC-CO-10001449 | P283: Technology | Q283: Copiers | R283: Hewlett Packard LaserJet 3310 Copier | S283: 1799.97 | T283: 5 | U283: 0.4 | V283: 239.996
A284: 8799 | B284: US-2013-150140 | C284: 2013 | D284: 41371 | E284: 41375 | F284: Standard Class | G284: VM-21685 | H284: Valerie Mitchum | I284: Home Office | J284: United States | K284: Burlington | L284: Vermont | M284: 05408 | N284: East | O284: TEC-PH-10002555 | P284: Technology | Q284: Phones | R284: Nortel Meridian M5316 Digital phone | S284: 1294.75 | T284: 5 | U284: 0 | V284: 336.635
A285: 282 | B285: US-2012-161991 | C285: 2012 | D285: 41178 | E285: 41180 | F285: Second Class | G285: SC-20725 | H285: Steven Cartwright | I285: Consumer | J285: United States | K285: Houston | L285: Texas | M285: 77070 | N285: Central | O285: TEC-PH-10001760 | P285: Technology | Q285: Phones | R285: Bose SoundLink Bluetooth Speaker | S285: 1114.4 | T285: 7 | U285: 0.2 | V285: 376.11
A286: 8796 | B286: CA-2011-162992 | C286: 2011 | D286: 40896 | E286: 40898 | F286: First Class | G286: BP-11095 | H286: Bart Pistole | I286: Corporate | J286: United States | K286: Los Angeles | L286: California | M286: 90008 | N286: West | O286: TEC-PH-10002085 | P286: Technology | Q286: Phones | R286: Clarity 53712 | S286: 211.168 | T286: 4 | U286: 0.2 | V286: 15.8376
A287: 8795 | B287: CA-2011-162992 | C287: 2011 | D287: 40896 | E287: 40898 | F287: First Class | G287: BP-11095 | H287: Bart Pistole | I287: Corporate | J287: United States | K287: Los Angeles | L287: California | M287: 90008 | N287: West | O287: TEC-PH-10001944 | P287: Technology | Q287: Phones | R287: Wi-Ex zBoost YX540 Cellular Phone Signal Booster | S287: 583.8 | T287: 5 | U287: 0.2 | V287: 72.975
A288: 285 | B288: CA-2012-130883 | C288: 2012 | D288: 41178 | E288: 41184 | F288: Standard Class | G288: TB-21520 | H288: Tracy Blumstein | I288: Consumer | J288: United States | K288: Portland | L288: Oregon | M288: 97206 | N288: West | O288: TEC-AC-10001956 | P288: Technology | Q288: Accessories | R288: Microsoft Arc Touch Mouse | S288: 239.8 | T288: 5 | U288: 0.2 | V288: 47.96
A289: 8792 | B289: CA-2014-162075 | C289: 2014 | D289: 41717 | E289: 41723 | F289: Standard Class | G289: TT-21220 | H289: Thomas Thornton | I289: Consumer | J289: United States | K289: Houston | L289: Texas | M289: 77041 | N289: Central | O289: TEC-PH-10001557 | P289: Technology | Q289: Phones | R289: Pyle PMP37LED | S289: 537.544 | T289: 7 | U289: 0.2 | V289: 47.0351
A290: 8788 | B290: CA-2014-145765 | C290: 2014 | D290: 41788 | E290: 41793 | F290: Standard Class | G290: CM-11815 | H290: Candace McMahon | I290: Corporate | J290: United States | K290: Phoenix | L290: Arizona | M290: 85023 | N290: West | O290: TEC-AC-10000844 | P290: Technology | Q290: Accessories | R290: Logitech Gaming G510s - Keyboard | S290: 271.968 | T290: 4 | U290: 0.2 | V290: 54.3936
A291: 8786 | B291: CA-2014-145765 | C291: 2014 | D291: 41788 | E291: 41793 | F291: Standard Class | G291: CM-11815 | H291: Candace McMahon | I291: Corporate | J291: United States | K291: Phoenix | L291: Arizona | M291: 85023 | N291: West | O291: TEC-PH-10001305 | P291: Technology | Q291: Phones | R291: Panasonic KX TS208W Corded phone | S291: 195.96 | T291: 5 | U291: 0.2 | V291: 19.596
A292: 8770 | B292: CA-2013-151148 | C292: 2013 | D292: 41530 | E292: 41531 | F292: Same Day | G292: PO-19180 | H292: Philisse Overcash | I292: Home Office | J292: United States | K292: Louisville | L292: Colorado | M292: 80027 | N292: West | O292: TEC-PH-10001870 | P292: Technology | Q292: Phones | R292: Lunatik TT5L-002 Taktik Strike Impact Protection System for iPhone 5 | S292: 146.952 | T292: 3 | U292: 0.2 | V292: 9.1845
A293: 8769 | B293: CA-2012-151722 | C293: 2012 | D293: 41187 | E293: 41191 | F293: Standard Class | G293: IL-15100 | H293: Ivan Liston | I293: Consumer | J293: United States | K293: Columbus | L293: Ohio | M293: 43229 | N293: East | O293: TEC-AC-10000892 | P293: Technology | Q293: Accessories | R293: NETGEAR N750 Dual Band Wi-Fi Gigabit Router | S293: 288 | T293: 4 | U293: 0.2 | V293: 57.6
A294: 8753 | B294: CA-2013-105662 | C294: 2013 | D294: 41400 | E294: 41404 | F294: Standard Class | G294: RB-19465 | H294: Rick Bensley | I294: Home Office | J294: United States | K294: Tallahassee | L294: Florida | M294: 32303 | N294: South | O294: TEC-PH-10001198 | P294: Technology | Q294: Phones | R294: Avaya 4621SW VoIP phone | S294: 177.48 | T294: 3 | U294: 0.2 | V294: 19.9665
...

Sheet my all pivot tables
A3: Row Labels | B3: Sum of Sales | C3: Sum of Profit | F3: Row Labels | G3: Sum of Profit | I3: Category | J3: Profit
A4: Jan | B4: 5539.796 | C4: 320.6542 | F4: Technology | G4: 19300.917 | I4: =F4 -> Technology | J4: =G4 -> 19300.917
A5: Feb | B5: 4950.902 | C5: 486.2289 | F5: Office Supplies | G5: 11714.305 | I5: =F5 -> Office Supplies | J5: =G5 -> 11714.305 | L5: Row Labels | M5: Sum of Sales | P5: Row Labels | Q5: Sum of Sales | S5: State | T5: Sales
A6: Mar | B6: 6850.226 | C6: 954.0345 | F6: Furniture | G6: 2180.1244 | I6: =F6 -> Furniture | J6: =G6 -> 2180.1244 | L6: Furniture | M6: 0.28537811 | P6: Connecticut | Q6: 5307.21 | S6: =P6 -> Connecticut | T6: =Q6 -> 5307.21 | V6: Row Labels | W6: Sum of Sales
A7: Apr | B7: 10327.692 | C7: 1574.4102 | F7: Grand Total | G7: 33195.346 | I7: =F7 -> Grand Total | J7: =G7 -> 33195.346 | L7: Office Supplies | M7: 0.3059806 | P7: Delaware | Q7: 13754.983 | S7: =P7 -> Delaware | T7: =Q7 -> 13754.983 | V7: Accessories | W7: 14836.79
A8: May | B8: 6889.933 | C8: 711.3313 | L8: Technology | M8: 0.40864129 | P8: District of Columbia | Q8: 77.76 | S8: =P8 -> District of Columbia | T8: =Q8 -> 77.76 | V8: Storage | W8: 20156.57
A9: Jun | B9: 12760.375 | C9: 3038.634 | L9: Grand Total | M9: 1 | P9: Maryland | Q9: 9451.6 | S9: =P9 -> Maryland | T9: =Q9 -> 9451.6 | V9: Copiers | W9: 24399.87
A10: Jul | B10: 13509.781 | C10: 818.6384 | P10: Massachusetts | Q10: 8143.076 | S10: =P10 -> Massachusetts | T10: =Q10 -> 8143.076 | V10: Chairs | W10: 31232.66
A11: Aug | B11: 21971.358 | C11: 2545.5305 | P11: New Hampshire | Q11: 1509.43 | S11: =P11 -> New Hampshire | T11: =Q11 -> 1509.43 | V11: Phones | W11: 36074.57
A12: Sep | B12: 32230.554 | C12: 2404.881 | P12: New Jersey | Q12: 9483.55 | S12: =P12 -> New Jersey | T12: =Q12 -> 9483.55 | V12: Grand Total | W12: 126700.46
A13: Oct | B13: 32490.744 | C13: 7725.647 | P13: New York | Q13: 93922.995 | S13: =P13 -> New York | T13: =Q13 -> 93922.995
A14: Nov | B14: 41523.965 | C14: 8821.0827 | P14: Ohio | Q14: 23421.362 | S14: =P14 -> Ohio | T14: =Q14 -> 23421.362
A15: Dec | B15: 24194.09 | C15: 3794.2735 | P15: Pennsylvania | Q15: 42688.306 | S15: =P15 -> Pennsylvania | T15: =Q15 -> 42688.306
A16: Grand Total | B16: 213239.42 | C16: 33195.346 | P16: Rhode Island | Q16: 3427.11 | S16: =P16 -> Rhode Island | T16: =Q16 -> 3427.11
P17: Vermont | Q17: 842.21 | S17: =P17 -> Vermont | T17: =Q17 -> 842.21
P18: West Virginia | Q18: 1209.824 | S18: =P18 -> West Virginia | T18: =Q18 -> 1209.824
P19: Grand Total | Q19: 213239.42 | S19: =P19 -> Grand Total | T19: =Q19 -> 213239.42
S20: =P20 -> 0 | T20: =Q20 -> 0
S21: =P21 -> 0 | T21: =Q21 -> 0
S22: =P22 -> 0 | T22: =Q22 -> 0
S23: =P23 -> 0 | T23: =Q23 -> 0
S24: =P24 -> 0 | T24: =Q24 -> 0
S25: =P25 -> 0 | T25: =Q25 -> 0
S26: =P26 -> 0 | T26: =Q26 -> 0
S27: =P27 -> 0 | T27: =Q27 -> 0
S28: =P28 -> 0 | T28: =Q28 -> 0
S29: =P29 -> 0 | T29: =Q29 -> 0
S30: =P30 -> 0 | T30: =Q30 -> 0
S31: =P31 -> 0 | T31: =Q31 -> 0
... S55: =P55 -> 0 | T55: =Q55 -> 0

Sheet kpi
A3: Row Labels | B3: Sum of Sales | D3: Row Labels | E3: Sum of Profit | G3: Row Labels | H3: Sum of Quantity | J3: Row Labels | K3: Count of Order ID | M3: Row Labels | N3: Sum of Profit Margine
A4: Jan | B4: 5539.796 | D4: Jan | E4: 320.6542 | G4: Jan | H4: 80 | J4: Jan | K4: 25 | M4: Jan | N4: 0.057881951
A5: Feb | B5: 4950.902 | D5: Feb | E5: 486.2289 | G5: Feb | H5: 97 | J5: Feb | K5: 28 | M5: Feb | N5: 0.098210165
A6: Mar | B6: 6850.226 | D6: Mar | E6: 954.0345 | G6: Mar | H6: 212 | J6: Mar | K6: 62 | M6: Mar | N6: 0.13927051
A7: Apr | B7: 10327.692 | D7: Apr | E7: 1574.4102 | G7: Apr | H7: 208 | J7: Apr | K7: 63 | M7: Apr | N7: 0.1524455
A8: May | B8: 6889.933 | D8: May | E8: 711.3313 | G8: May | H8: 193 | J8: May | K8: 57 | M8: May | N8: 0.10324212
A9: Jun | B9: 12760.375 | D9: Jun | E9: 3038.634 | G9: Jun | H9: 242 | J9: Jun | K9: 61 | M9: Jun | N9: 0.23813046
A10: Jul | B10: 13509.781 | D10: Jul | E10: 818.6384 | G10: Jul | H10: 302 | J10: Jul | K10: 79 | M10: Jul | N10: 0.060595979
A11: Aug | B11: 21971.358 | D11: Aug | E11: 2545.5305 | G11: Aug | H11: 225 | J11: Aug | K11: 52 | M11: Aug | N11: 0.11585677
A12: Sep | B12: 32230.554 | D12: Sep | E12: 2404.881 | G12: Sep | H12: 504 | J12: Sep | K12: 147 | M12: Sep | N12: 0.074614945
A13: Oct | B13: 32490.744 | D13: Oct | E13: 7725.647 | G13: Oct | H13: 329 | J13: Oct | K13: 86 | M13: Oct | N13: 0.23777994
A14: Nov | B14: 41523.965 | D14: Nov | E14: 8821.0827 | G14: Nov | H14: 505 | J14: Nov | K14: 121 | M14: Nov | N14: 0.21243354
A15: Dec | B15: 24194.09 | D15: Dec | E15: 3794.2735 | G15: Dec | H15: 518 | J15: Dec | K15: 141 | M15: Dec | N15: 0.15682646
A16: Grand Total | B16: 213239.42 | D16: Grand Total | E16: 33195.346 | G16: Grand Total | H16: 3415 | J16: Grand Total | K16: 922 | M16: Grand Total | N16: 0.15567172
B17: =B16 -> 213239.42 | E17: =E16 -> 33195.346 | H17: =H16 -> 3415 | K17: =K16 -> 922 | N17: =N16 -> 0.15567172

Sheet KPI YOY
A3: Row Labels | B3: Sum of Sales | C3: Sum of Profit | D3: Sum of Quantity | E3: Count of Order ID | F3: Sum of Profit Margine
A4: 2011 | B4: 128680.46 | C4: 17059.61 | D4: 1986 | E4: 517 | F4: 0.13257343
A5: 2012 | B5: 156332.06 | C5: 21091.013 | D5: 2382 | E5: 644 | F5: 0.13491163
A6: 2013 | B6: 180529.31 | C6: 20176.811 | D6: 2835 | E6: 765 | F6: 0.11176474
A7: 2014 | B7: 213239.42 | C7: 33195.346 | D7: 3415 | E7: 922 | F7: 0.15567172
I8: =(B7/B6)-1 -> 0.18119 | J8: =(C7/C6)-1 -> 0.64522261 | K8: =(D7/D6)-1 -> 0.20458554 | L8: =(E7/E6)-1 -> 0.20522876 | M8: =(F7/F6)-1 -> 0.39285179

Sheet Data
A1: Row ID | B1: Order ID | C1: Year | D1: Order Date | E1: Ship Date | F1: Ship Mode | G1: Customer ID | H1: Customer Name | I1: Segment | J1: Country | K1: City | L1: State | M1: Postal Code | N1: Region | O1: Product ID | P1: Category | Q1: Sub-Category | R1: Product Name | S1: Sales | T1: Quantity | U1: Discount | V1: Profit
A2: 1 | B2: CA-2013-152156 | C2: =YEAR(Data!$D2) -> 2013 | D2: 41587 | E2: 41590 | F2: Second Class | G2: CG-12520 | H2: Claire Gute | I2: Consumer | J2: United States | K2: Henderson | L2: Kentucky | M2: 42420 | N2: South | O2: FUR-BO-10001798 | P2: Furniture | Q2: Bookcases | R2: Bush Somerset Collection Bookcase | S2: 261.96 | T2: 2 | U2: 0 | V2: 41.9136
A3: 2 | B3: CA-2013-152156 | C3: =YEAR(Data!$D3) -> 2013 | D3: 41587 | E3: 41590 | F3: Second Class | G3: CG-12520 | H3: Claire Gute | I3: Consumer | J3: United States | K3: Henderson | L3: Kentucky | M3: 42420 | N3: South | O3: FUR-CH-10000454 | P3: Furniture | Q3: Chairs | R3: Hon Deluxe Fabric Upholstered Stacking Chairs, Rounded Back | S3: 731.94 | T3: 3 | U3: 0 | V3: 219.582
A4: 3 | B4: CA-2013-138688 | C4: =YEAR(Data!$D4) -> 2013 | D4: 41438 | E4: 41442 | F4: Second Class | G4: DV-13045 | H4: Darrin Van Huff | I4: Corporate | J4: United States | K4: Los Angeles | L4: California | M4: 90036 | N4: West | O4: OFF-LA-10000240 | P4: Office Supplies | Q4: Labels | R4: Self-Adhesive Address Labels for Typewriters by Universal | S4: 14.62 | T4: 2 | U4: 0 | V4: 6.8714
A5: 4 | B5: US-2012-108966 | C5: =YEAR(Data!$D5) -> 2012 | D5: 41193 | E5: 41200 | F5: Standard Class | G5: SO-20335 | H5: Sean O'Donnell | I5: Consumer | J5: United States | K5: Fort Lauderdale | L5: Florida | M5: 33311 | N5: South | O5: FUR-TA-10000577 | P5: Furniture | Q5: Tables | R5: Bretford CR4500 Series Slim Rectangular Table | S5: 957.5775 | T5: 5 | U5: 0.45 | V5: -383.031
A6: 5 | B6: US-2012-108966 | C6: =YEAR(Data!$D6) -> 2012 | D6: 41193 | E6: 41200 | F6: Standard Class | G6: SO-20335 | H6: Sean O'Donnell | I6: Consumer | J6: United States | K6: Fort Lauderdale | L6: Florida | M6: 33311 | N6: South | O6: OFF-ST-10000760 | P6: Office Supplies | Q6: Storage | R6: Eldon Fold 'N Roll Cart System | S6: 22.368 | T6: 2 | U6: 0.2 | V6: 2.5164
A7: 6 | B7: CA-2011-115812 | C7: =YEAR(Data!$D7) -> 2011 | D7: 40703 | E7: 40708 | F7: Standard Class | G7: BH-11710 | H7: Brosina Hoffman | I7: Consumer | J7: United States | K7: Los Angeles | L7: California | M7: 90032 | N7: West | O7: FUR-FU-10001487 | P7: Furniture | Q7: Furnishings | R7: Eldon Expressions Wood and Plastic Desk Accessories, Cherry Wood | S7: 48.86 | T7: 7 | U7: 0 | V7: 14.1694
A8: 7 | B8: CA-2011-115812 | C8: =YEAR(Data!$D8) -> 2011 | D8: 40703 | E8: 40708 | F8: Standard Class | G8: BH-11710 | H8: Brosina Hoffman | I8: Consumer | J8: United States | K8: Los Angeles | L8: California | M8: 90032 | N8: West | O8: OFF-AR-10002833 | P8: Office Supplies | Q8: Art | R8: Newell 322 | S8: 7.28 | T8: 4 | U8: 0 | V8: 1.9656
A9: 8 | B9: CA-2011-115812 | C9: =YEAR(Data!$D9) -> 2011 | D9: 40703 | E9: 40708 | F9: Standard Class | G9: BH-11710 | H9: Brosina Hoffman | I9: Consumer | J9: United States | K9: Los Angeles | L9: California | M9: 90032 | N9: West | O9: TEC-PH-10002275 | P9: Technology | Q9: Phones | R9: Mitel 5320 IP Phone VoIP phone | S9: 907.152 | T9: 6 | U9: 0.2 | V9: 90.7152
A10: 9 | B10: CA-2011-115812 | C10: =YEAR(Data!$D10) -> 2011 | D10: 40703 | E10: 40708 | F10: Standard Class | G10: BH-11710 | H10: Brosina Hoffman | I10: Consumer | J10: United States | K10: Los Angeles | L10: California | M10: 90032 | N10: West | O10: OFF-BI-10003910 | P10: Office Supplies | Q10: Binders | R10: DXL Angle-View Binders with Locking Rings by Samsill | S10: 18.504 | T10: 3 | U10: 0.2 | V10: 5.7825
A11: 10 | B11: CA-2011-115812 | C11: =YEAR(Data!$D11) -> 2011 | D11: 40703 | E11: 40708 | F11: Standard Class | G11: BH-11710 | H11: Brosina Hoffman | I11: Consumer | J11: United States | K11: Los Angeles | L11: California | M11: 90032 | N11: West | O11: OFF-AP-10002892 | P11: Office Supplies | Q11: Appliances | R11: Belkin F5C206VTEL 6 Outlet Surge | S11: 114.9 | T11: 5 | U11: 0 | V11: 34.47
A12: 11 | B12: CA-2011-115812 | C12: =YEAR(Data!$D12) -> 2011 | D12: 40703 | E12: 40708 | F12: Standard Class | G12: BH-11710 | H12: Brosina Hoffman | I12: Consumer | J12: United States | K12: Los Angeles | L12: California | M12: 90032 | N12: West | O12: FUR-TA-10001539 | P12: Furniture | Q12: Tables | R12: Chromcraft Rectangular Conference Tables | S12: 1706.184 | T12: 9 | U12: 0.2 | V12: 85.3092
A13: 12 | B13: CA-2011-115812 | C13: =YEAR(Data!$D13) -> 2011 | D13: 40703 | E13: 40708 | F13: Standard Class | G13: BH-11710 | H13: Brosina Hoffman | I13: Consumer | J13: United States | K13: Los Angeles | L13: California | M13: 90032 | N13: West | O13: TEC-PH-10002033 | P13: Technology | Q13: Phones | R13: Konftel 250 Conference phone - Charcoal black | S13: 911.424 | T13: 4 | U13: 0.2 | V13: 68.3568
... A2235: 2234 | B2235: CA-2012-123232 | C2235: =YEAR(Data!$D2235) -> 2012 | D2235: 41257 | E2235: 41259 | F2235: Second Class | G2235: DJ-13630 | H2235: Doug Jacobs | I2235: Consumer | J2235: United States | K2235: Portland | L2235: Oregon | M2235: 97206 | N2235: West | O2235: TEC-PH-10001051 | P2235: Technology | Q2235: Phones | R2235: HTC One | S2235: 319.968 | T2235: 4 | U2235: 0.2 | V2235: 35.9964
A2236: 2235 | B2236: CA-2014-104066 | C2236: =YEAR(Data!$D2236) -> 2014 | D2236: 41979 | E2236: 41984 | F2236: Standard Class | G2236: QJ-19255 | H2236: Quincy Jones | I2236: Corporate | J2236: United States | K2236: Burlington | L2236: Vermont | M2236: 05408 | N2236: East | O2236: TEC-AC-10001013 | P2236: Technology | Q2236: Accessories | R2236: Logitech ClearChat Comfort/USB Headset H390 | S2236: 205.03 | T2236: 7 | U2236: 0 | V2236: 67.6599
A2237: 2236 | B2237: CA-2012-145849 | C2237: =YEAR(Data!$D2237) -> 2012 | D2237: 41167 | E2237: 41169 | F2237: Second Class | G2237: CT-11995 | H2237: Carol Triggs | I2237: Consumer | J2237: United States | K2237: Indianapolis | L2237: Indiana | M2237: 46203 | N2237: Central | O2237: OFF-ST-10000025 | P2237: Office Supplies | Q2237: Storage | R2237: Fellowes Stor/Drawer Steel Plus Storage Drawers | S2237: 190.86 | T2237: 2 | U2237: 0 | V2237: 11.4516
A2238: 2237 | B2238: CA-2012-145849 | C2238: =YEAR(Data!$D2238) -> 2012 | D2238: 41167 | E2238: 41169 | F2238: Second Class | G2238: CT-11995 | H2238: Carol Triggs | I2238: Consumer | J2238: United States | K2238: Indianapolis | L2238: Indiana | M2238: 46203 | N2238: Central | O2238: OFF-AR-10000817 | P2238: Office Supplies | Q2238: Art | R2238: Manco Dry-Lighter Erasable Highlighter | S2238: 24.32 | T2238: 8 | U2238: 0 | V2238: 8.2688
A2239: 2238 | B2239: CA-2013-122322 | C2239: =YEAR(Data!$D2239) -> 2013 | D2239: 41471 | E2239: 41477 | F2239: Standard Class | G2239: RH-19510 | H2239: Rick Huthwaite | I2239: Home Office | J2239: United States | K2239: Provo | L2239: Utah | M2239: 84604 | N2239: West | O2239: OFF-SU-10000952 | P2239: Office Supplies | Q2239: Supplies | R2239: Fiskars Home & Office Scissors | S2239: 44.4 | T2239: 5 | U2239: 0 | V2239: 12.432
A2240: 2239 | B2240: CA-2014-166849 | C2240: =YEAR(Data!$D2240) -> 2014 | D2240: 41750 | E2240: 41756 | F2240: Standard Class | G2240: SJ-20125 | H2240: Sanjit Jacobs | I2240: Home Office | J2240: United States | K2240: Chicago | L2240: Illinois | M2240: 60610 | N2240: Central | O2240: FUR-FU-10004597 | P2240: Furniture | Q2240: Furnishings | R2240: Eldon Cleatmat Chair Mats for Medium Pile Carpets | S2240: 44.4 | T2240: 2 | U2240: 0.6 | V2240: -52.17
A2241: 2240 | B2241: CA-2013-146633 | C2241: =YEAR(Data!$D2241) -> 2013 | D2241: 41594 | E2241: 41596 | F2241: Second Class | G2241: TG-21310 | H2241: Toby Gnade | I2241: Consumer | J2241: United States | K2241: Los Angeles | L2241: California | M2241: 90049 | N2241: West | O2241: OFF-BI-10003527 | P2241: Office Supplies | Q2241: Binders | R2241: Fellowes PB500 Electric Punch Plastic Comb Binding Machine with Manual Bind | S2241: 1016.792 | T2241: 1 | U2241: 0.2 | V2241: 381.297
A2242: 2241 | B2242: CA-2013-146633 | C2242: =YEAR(Data!$D2242) -> 2013 | D2242: 41594 | E2242: 41596 | F2242: Second Class | G2242: TG-21310 | H2242: Toby Gnade | I2242: Consumer | J2242: United States | K2242: Los Angeles | L2242: California | M2242: 90049 | N2242: West | O2242: OFF-BI-10002982 | P2242: Office Supplies | Q2242: Binders | R2242: Avery Self-Adhesive Photo Pockets for Polaroid Photos | S2242: 38.136 | T2242: 7 | U2242: 0.2 | V2242: 13.3476
A2243: 2242 | B2243: US-2013-126893 | C2243: =YEAR(Data!$D2243) -> 2013 | D2243: 41605 | E2243: 41610 | F2243: Standard Class | G2243: CT-11995 | H2243: Carol Triggs | I2243: Consumer | J2243: United States | K2243: Philadelphia | L2243: Pennsylvania | M2243: 19134 | N2243: East | O2243: TEC-PH-10004165 | P2243: Technology | Q2243: Phones | R2243: Mitel MiVoice 5330e IP Phone | S2243: 494.982 | T2243: 3 | U2243: 0.4 | V2243: -115.4958
A2244: 2243 | B2244: CA-2014-103380 | C2244: =YEAR(Data!$D2244) -> 2014 | D2244: 41965 | E2244: 41969 | F2244: Standard Class | G2244: BF-11005 | H2244: Barry Franz | I2244: Home Office | J2244: United States | K2244: Pasadena | L2244: California | M2244: 91104 | N2244: West | O2244: OFF-ST-10003442 | P2244: Office Supplies | Q2244: Storage | R2244: Eldon Portable Mobile Manager | S2244: 56.56 | T2244: 2 | U2244: 0 | V2244: 15.2712
A2245: 2244 | B2245: CA-2014-103380 | C2245: =YEAR(Data!$D2245) -> 2014 | D2245: 41965 | E2245: 41969 | F2245: Standard Class | G2245: BF-11005 | H2245: Barry Franz | I2245: Home Office | J2245: United States | K2245: Pasadena | L2245: California | M2245: 91104 | N2245: West | O2245: OFF-AR-10003856 | P2245: Office Supplies | Q2245: Art | R2245: Newell 344 | S2245: 5.56 | T2245: 2 | U2245: 0 | V2245: 1.4456
A2246: 2245 | B2246: CA-2014-103380 | C2246: =YEAR(Data!$D2246) -> 2014 | D2246: 41965 | E2246: 41969 | F2246: Standard Class | G2246: BF-11005 | H2246: Barry Franz | I2246: Home Office | J2246: United States | K2246: Pasadena | L2246: California | M2246: 91104 | N2246: West | O2246: OFF-FA-10004248 | P2246: Office Supplies | Q2246: Fasteners | R2246: Advantus T-Pin Paper Clips | S2246: 9.02 | T2246: 2 | U2246: 0 | V2246: 3.5178
A2247: 2246 | B2247: CA-2014-103380 | C2247: =YEAR(Data!$D2247) -> 2014 | D2247: 41965 | E2247: 41969 | F2247: Standard Class | G2247: BF-11005 | H2247: Barry Franz | I2247: Home Office | J2247: United States | K2247: Pasadena | L2247: California | M2247: 91104 | N2247: West | O2247: OFF-AP-10001492 | P2247: Office Supplies | Q2247: Appliances | R2247: Acco Six-Outlet Power Strip, 4' Cord Length | S2247: 8.62 | T2247: 1 | U2247: 0 | V2247: 2.2412
A2248: 2247 | B2248: CA-2014-103380 | C2248: =YEAR(Data!$D2248) -> 2014 | D2248: 41965 | E2248: 41969 | F2248: Standard Class | G2248: BF-11005 | H2248: Barry Franz | I2248: Home Office | J2248: United States | K2248: Pasadena | L2248: California | M2248: 91104 | N2248: West | O2248: TEC-PH-10004165 | P2248: Technology | Q2248: Phones | R2248: Mitel MiVoice 5330e IP Phone | S2248: 659.976 | T2248: 3 | U2248: 0.2 | V2248: 49.4982
... A5275: 5274 | B5275: US-2013-158309 | C5275: =YEAR(Data!$D5275) -> 2013 | D5275: 41605 | E5275: 41608 | F5275: First Class | G5275: PA-19060 | H5275: Pete Armstrong | I5275: Home Office | J5275: United States | K5275: Miami | L5275: Florida | M5275: 33142 | N5275: South | O5275: OFF-BI-10000145 | P5275: Office Supplies | Q5275: Binders | R5275: Zipper Ring Binder Pockets | S5275: 3.744 | T5275: 4 | U5275: 0.7 | V5275: -2.6208
A5276: 5275 | B5276: CA-2012-162887 | C5276: =YEAR(Data!$D5276) -> 2012 | D5276: 41220 | E5276: 41222 | F5276: Second Class | G5276: SV-20785 | H5276: Stewart Visinsky | I5276: Consumer | J5276: United States | K5276: Burlington | L5276: Vermont | M5276: 05408 | N5276: East | O5276: FUR-CH-10000595 | P5276: Furniture | Q5276: Chairs | R5276: Safco Contoured Stacking Chairs | S5276: 715.2 | T5276: 3 | U5276: 0 | V5276: 178.8
A5277: 5276 | B5277: CA-2014-147333 | C5277: =YEAR(Data!$D5277) -> 2014 | D5277: 41988 | E5277: 41994 | F5277: Standard Class | G5277: KL-16555 | H5277: Kelly Lampkin | I5277: Corporate | J5277: United States | K5277: Fayetteville | L5277: Arkansas | M5277: 72701 | N5277: South | O5277: TEC-AC-10004469 | P5277: Technology | Q5277: Accessories | R5277: Microsoft Sculpt Comfort Mouse | S5277: 159.8 | T5277: 4 | U5277: 0 | V5277: 70.312
A5278: 5277 | B5278: CA-2014-147333 | C5278: =YEAR(Data!$D5278) -> 2014 | D5278: 41988 | E5278: 41994 | F5278: Standard Class | G5278: KL-16555 | H5278: Kelly Lampkin | I5278: Corporate | J5278: United States | K5278: Fayetteville | L5278: Arkansas | M5278: 72701 | N5278: South | O5278: TEC-AC-10003038 | P5278: Technology | Q5278: Accessories | R5278: Kingston Digital DataTraveler 16GB USB 2.0 | S5278: 44.75 | T5278: 5 | U5278: 0 | V5278: 8.5025
A5279: 5278 | B5279: CA-2011-113859 | C5279: =YEAR(Data!$D5279) -> 2011 | D5279: 40799 | E5279: 40803 | F5279: Standard Class | G5279: BC-11125 | H5279: Becky Castell | I5279: Home Office | J5279: United States | K5279: Odessa | L5279: Texas | M5279: 79762 | N5279: Central | O5279: FUR-CH-10004698 | P5279: Furniture | Q5279: Chairs | R5279: Padded Folding Chairs, Black, 4/Carton | S5279: 340.116 | T5279: 6 | U5279: 0.3 | V5279: -9.7176
A5280: 5279 | B5280: CA-2011-159681 | C5280: =YEAR(Data!$D5280) -> 2011 | D5280: 40884 | E5280: 40890 | F5280: Standard Class | G5280: PO-18850 | H5280: Patrick O'Brill | I5280: Consumer | J5280: United States | K5280: Virginia Beach | L5280: Virginia | M5280: 23464 | N5280: South | O5280: OFF-PA-10003641 | P5280: Office Supplies | Q5280: Paper | R5280: Xerox 1909 | S5280: 105.52 | T5280: 4 | U5280: 0 | V5280: 48.5392
A5281: 5280 | B5281: US-2014-104094 | C5281: =YEAR(Data!$D5281) -> 2014 | D5281: 41890 | E5281: 41894 | F5281: Standard Class | G5281: AG-10675 | H5281: Anna Gayman | I5281: Consumer | J5281: United States | K5281: Milwaukee | L5281: Wisconsin | M5281: 53209 | N5281: Central | O5281: TEC-AC-10002134 | P5281: Technology | Q5281: Accessories | R5281: Rosewill 107 Normal Keys USB Wired Standard Keyboard | S5281: 13.48 | T5281: 1 | U5281: 0 | V5281: 1.8872
A5282: 5281 | B5282: CA-2014-152709 | C5282: =YEAR(Data!$D5282) -> 2014 | D5282: 41920 | E5282: 41925 | F5282: Standard Class | G5282: DB-13210 | H5282: Dean Braden | I5282: Consumer | J5282: United States | K5282: Detroit | L5282: Michigan | M5282: 48234 | N5282: Central | O5282: OFF-ST-10001837 | P5282: Office Supplies | Q5282: Storage | R5282: SAFCO Mobile Desk Side File, Wire Frame | S5282: 85.52 | T5282: 2 | U5282: 0 | V5282: 22.2352
A5283: 5282 | B5283: CA-2012-105158 | C5283: =YEAR(Data!$D5283) -> 2012 | D5283: 41157 | E5283: 41162 | F5283: Standard Class | G5283: SP-20860 | H5283: Sung Pak | I5283: Corporate | J5283: United States | K5283: Rochester | L5283: Minnesota | M5283: 55901 | N5283: Central | O5283: FUR-FU-10001706 | P5283: Furniture | Q5283: Furnishings | R5283: Longer-Life Soft White Bulbs | S5283: 6.16 | T5283: 2 | U5283: 0 | V5283: 2.9568
A5284: 5283 | B5284: CA-2012-105158 | C5284: =YEAR(Data!$D5284) -> 2012 | D5284: 41157 | E5284: 41162 | F5284: Standard Class | G5284: SP-20860 | H5284: Sung Pak | I5284: Corporate | J5284: United States | K5284: Rochester | L5284: Minnesota | M5284: 55901 | N5284: Central | O5284: OFF-PA-10001970 | P5284: Office Supplies | Q5284: Paper | R5284: Xerox 1881 | S5284: 36.84 | T5284: 3 | U5284: 0 | V5284: 17.3148
A5285: 5284 | B5285: CA-2011-133424 | C5285: =YEAR(Data!$D5285) -> 2011 | D5285: 40632 | E5285: 40637 | F5285: Standard Class | G5285: Dl-13600 | H5285: Dorris liebe | I5285: Corporate | J5285: United States | K5285: Seattle | L5285: Washington | M5285: 98105 | N5285: West | O5285: OFF-ST-10002957 | P5285: Office Supplies | Q5285: Storage | R5285: Sterilite Show Offs Storage Containers | S5285: 15.84 | T5285: 3 | U5285: 0 | V5285: 0
A5286: 5285 | B5286: CA-2011-133424 | C5286: =YEAR(Data!$D5286) -> 2011 | D5286: 40632 | E5286: 40637 | F5286: Standard Class | G5286: Dl-13600 | H5286: Dorris liebe | I5286: Corporate | J5286: United States | K5286: Seattle | L5286: Washington | M5286: 98105 | N5286: West | O5286: OFF-LA-10002312 | P5286: Office Supplies | Q5286: Labels | R5286: Avery 490 | S5286: 44.4 | T5286: 3 | U5286: 0 | V5286: 22.2
A5287: 5286 | B5287: CA-2014-105991 | C5287: =YEAR(Data!$D5287) -> 2014 | D5287: 41765 | E5287: 41766 | F5287: First Class | G5287: LH-17020 | H5287: Lisa Hazard | I5287: Consumer | J5287: United States | K5287: Louisville | L5287: Colorado | M5287: 80027 | N5287: West | O5287: OFF-EN-10002600 | P5287: Office Supplies | Q5287: Envelopes | R5287: Redi-Strip #10 Envelopes, 4 1/8 x 9 1/2 | S5287: 21.24 | T5287: 9 | U5287: 0.2 | V5287: 7.434
...

Sheet layout
A11: `` | B11: =#REF! -> #REF!

Sheet Dashboard1
